import { AssertionError, expect } from 'chai';
import * as zk from 'zksync-ethers';
import path, { resolve } from 'path';
import util from 'util';

import { Deployer } from '@matterlabs/hardhat-zksync-deploy/src/deployer';
import { ZkSyncArtifact } from '@matterlabs/hardhat-zksync-deploy/src/types';
import { PANIC_CODES } from '@nomicfoundation/hardhat-chai-matchers/internal/reverted/panic';

import { runSuccessfulAsserts, runFailedAsserts, useEnvironmentWithLocalSetup } from '../helpers';
import '../../src/internal/add-chai-matchers';
import { HttpNetworkConfig } from 'hardhat/types';

const RICH_WALLET_PK = '0x7726827caac94a7f9e1b160f7ea819f172f7b6f9d2a97f992c38edeab82d4110';

describe('INTEGRATION: Reverted with panic', function () {
    describe('with the local setup', function () {
        useEnvironmentWithLocalSetup('hardhat-project');

        runTests();
    });

    function runTests() {
        let matchers: zk.Contract;
        let provider: zk.Provider;
        let wallet: zk.Wallet;
        let deployer: Deployer;
        let artifact: ZkSyncArtifact;

        beforeEach('deploy matchers contract', async function () {
            const hre = await import("hardhat");
            provider = new zk.Provider((hre.network.config as HttpNetworkConfig).url);
            wallet = new zk.Wallet(RICH_WALLET_PK, provider);

            deployer = new Deployer(this.hre, wallet);
            artifact = await deployer.loadArtifact('Matchers');
            matchers = await deployer.deploy(artifact);
        });

        describe('calling a method that succeeds', function () {
            it('successful asserts', async function () {
                //wait some time to update 
                await new Promise((resolve) => setTimeout(resolve, 1000));
                await runSuccessfulAsserts({
                    matchers,
                    method: 'succeeds',
                    successfulAssert: (x) => expect(x).not.to.be.revertedWithPanic(),
                });
                //wait some time to update 
                await new Promise((resolve) => setTimeout(resolve, 1000));

                await runSuccessfulAsserts({
                    matchers,
                    method: 'succeeds',
                    successfulAssert: (x) => expect(x).not.to.be.revertedWithPanic(PANIC_CODES.ASSERTION_ERROR),
                });
            });

            it('failed asserts', async function () {
                //wait some time to update 
                await new Promise((resolve) => setTimeout(resolve, 1000));
                await runFailedAsserts({
                    matchers,
                    method: 'succeeds',
                    failedAssert: (x) => expect(x).to.be.revertedWithPanic(),
                    failedAssertReason:
                        "Expected transaction to be reverted with some panic code, but it didn't revert",
                });
                //wait some time to update 
                await new Promise((resolve) => setTimeout(resolve, 1000));

                await runFailedAsserts({
                    matchers,
                    method: 'succeeds',
                    failedAssert: (x) => expect(x).to.be.revertedWithPanic(PANIC_CODES.ASSERTION_ERROR),
                    failedAssertReason:
                        "Expected transaction to be reverted with panic code 0x01 (Assertion error), but it didn't revert",
                });
            });
        });

        describe('calling a method that reverts without a reason', function () {
            it('successful asserts', async function () {
                await runSuccessfulAsserts({
                    matchers,
                    method: 'revertsWithoutReason',
                    successfulAssert: (x) => expect(x).to.not.be.revertedWithPanic(),
                });

                await runSuccessfulAsserts({
                    matchers,
                    method: 'revertsWithoutReason',
                    successfulAssert: (x) => expect(x).to.not.be.revertedWithPanic(PANIC_CODES.ASSERTION_ERROR),
                });
            });
        });

        describe('calling a method that reverts with a reason string', function () {
            it('successful asserts', async function () {
                await runSuccessfulAsserts({
                    matchers,
                    method: 'revertsWith',
                    args: ['some reason'],
                    successfulAssert: (x) => expect(x).to.not.be.revertedWithPanic(),
                });

                await runSuccessfulAsserts({
                    matchers,
                    method: 'revertsWith',
                    args: ['some reason'],
                    successfulAssert: (x) => expect(x).to.not.be.revertedWithPanic(PANIC_CODES.ASSERTION_ERROR),
                });
            });

            it('failed asserts', async function () {
                await runFailedAsserts({
                    matchers,
                    method: 'revertsWith',
                    args: ['some reason'],
                    failedAssert: (x) => expect(x).to.be.revertedWithPanic(),
                    failedAssertReason:
                        "Expected transaction to be reverted with some panic code, but it reverted with reason 'some reason'",
                });

                await runFailedAsserts({
                    matchers,
                    method: 'revertsWith',
                    args: ['some reason'],
                    failedAssert: (x) => expect(x).to.be.revertedWithPanic(PANIC_CODES.ASSERTION_ERROR),
                    failedAssertReason:
                        "Expected transaction to be reverted with panic code 0x01 (Assertion error), but it reverted with reason 'some reason'",
                });
            });
        });

        describe('calling a method that reverts with a panic code', function () {
            it('successful asserts', async function () {
                await runSuccessfulAsserts({
                    matchers,
                    method: 'panicAssert',
                    successfulAssert: (x) => expect(x).to.be.revertedWithPanic(),
                });

                await runSuccessfulAsserts({
                    matchers,
                    method: 'panicAssert',
                    successfulAssert: (x) => expect(x).to.be.revertedWithPanic(PANIC_CODES.ASSERTION_ERROR),
                });
            });

            it('failed asserts', async function () {
                await runFailedAsserts({
                    matchers,
                    method: 'panicAssert',
                    failedAssert: (x) => expect(x).to.not.be.revertedWithPanic(),
                    failedAssertReason:
                        'Expected transaction NOT to be reverted with some panic code, but it reverted with panic code 0x01 (Assertion error)',
                });

                await runFailedAsserts({
                    matchers,
                    method: 'panicAssert',
                    failedAssert: (x) => expect(x).to.not.be.revertedWithPanic(PANIC_CODES.ASSERTION_ERROR),
                    failedAssertReason:
                        'Expected transaction NOT to be reverted with panic code 0x01 (Assertion error), but it was',
                });

                await runFailedAsserts({
                    matchers,
                    method: 'panicAssert',
                    failedAssert: (x) => expect(x).to.be.revertedWithPanic(PANIC_CODES.ARITHMETIC_UNDER_OR_OVERFLOW),
                    failedAssertReason:
                        'Expected transaction to be reverted with panic code 0x11 (Arithmetic operation underflowed or overflowed outside of an unchecked block), but it reverted with panic code 0x01 (Assertion error)',
                });
            });
        });

        describe('calling a method that reverts with a custom error', function () {
            it('successful asserts', async function () {
                await runSuccessfulAsserts({
                    matchers,
                    method: 'revertWithSomeCustomError',
                    successfulAssert: (x) => expect(x).to.not.be.revertedWithPanic(),
                });

                await runSuccessfulAsserts({
                    matchers,
                    method: 'revertWithSomeCustomError',
                    successfulAssert: (x) => expect(x).to.not.be.revertedWithPanic(PANIC_CODES.ASSERTION_ERROR),
                });
            });

            it('failed asserts', async function () {
                await runFailedAsserts({
                    matchers,
                    method: 'revertWithSomeCustomError',
                    failedAssert: (x) => expect(x).to.be.revertedWithPanic(),
                    failedAssertReason:
                        'Expected transaction to be reverted with some panic code, but it reverted with a custom error',
                });

                await runFailedAsserts({
                    matchers,
                    method: 'revertWithSomeCustomError',
                    failedAssert: (x) => expect(x).to.be.revertedWithPanic(PANIC_CODES.ASSERTION_ERROR),
                    failedAssertReason:
                        'Expected transaction to be reverted with panic code 0x01 (Assertion error), but it reverted with a custom error',
                });
            });
        });

        describe('accepted panic code values', function () {
            it('number', async function () {
                await runSuccessfulAsserts({
                    matchers,
                    method: 'succeeds',
                    successfulAssert: (x) => expect(x).not.to.be.revertedWithPanic(1),
                });
            });

            it('bigint', async function () {
                await runSuccessfulAsserts({
                    matchers,
                    method: 'succeeds',
                    successfulAssert: (x) => expect(x).not.to.be.revertedWithPanic(1),
                });
            });

            it('string', async function () {
                await runSuccessfulAsserts({
                    matchers,
                    method: 'succeeds',
                    successfulAssert: (x) => expect(x).not.to.be.revertedWithPanic('1'),
                });
            });

            it("ethers's BigNumber", async function () {
                await runSuccessfulAsserts({
                    matchers,
                    method: 'succeeds',
                    successfulAssert: (x) => expect(x).not.to.be.revertedWithPanic(1),
                });
            });
        });

        describe('invalid values', function () {
            it('non-errors as subject', async function () {
                await expect(expect(Promise.reject({})).to.be.revertedWithPanic(1)).to.be.rejectedWith(
                    AssertionError,
                    'Expected an Error object'
                );
            });
        });

        describe('stack traces', function () {
            it('includes test file', async function () {
                try {
                    await expect(matchers.panicAssert()).to.not.be.revertedWithPanic();
                } catch (e: any) {
                    expect(util.inspect(e)).to.include(path.join('test', 'reverted', 'revertedWithPanic.ts'));

                    return;
                }

                expect.fail('Expected an exception but none was thrown');
            });
        });
    }
});
